Workbook

Sheet 品番
A1: Active | B1: 品番 | C1: 区分 | D1: 名称 | E1: 製造元 | F1: ハードウェア | G1: 機種 | H1: 帳票No | I1: バージョン | J1: 備考
A2: ○ | B2: 17301-44340 | C2: ディスプレイ | E2: DSD | F2: DP250 | G2: 共通 | H2: =_xlfn.XLOOKUP(B2&"-00",改定!N:N,改定!E:E) -> 0 | J2: ザウアーダンフォス社製DP250、ファクトリーツールとして使用
A3: E | B3: 17301-43650 | C3: ディスプレイ | E3: DSD | F3: 5.7"COLOR DISPLAY WITH OUT VIDEO | G3: 5.7'ディスプレイ | H3: =_xlfn.XLOOKUP(B3&"-00",改定!N:N,改定!E:E) -> 33457 | J3: カメラなし
A4: E | B4: 17301-43651 | C4: ディスプレイ | E4: DSD | F4: 5.7"COLOR DISPLAY WITH VIDEO | H4: =_xlfn.XLOOKUP(B4&"-00",改定!N:N,改定!E:E) -> B001137 | J4: カメラあり
A5: E | B5: 17301-43660 | C5: ディスプレイ | E5: DSD | F5: 5.7"COLOR DISPLAY WITH OUT VIDEO | H5: =_xlfn.XLOOKUP(B5&"-00",改定!N:N,改定!E:E) -> M001181 | J5: カメラなし
A6: E | B6: 17301-43661 | C6: ディスプレイ | E6: DSD | F6: 5.7"COLOR DISPLAY WITH VIDEO | H6: =_xlfn.XLOOKUP(B6&"-00",改定!N:N,改定!E:E) -> M001181 | J6: カメラあり
A7: ○ | B7: 17301-43664 | C7: ディスプレイ | E7: DSD | F7: 5.7"COLOR DISPLAY WITH OUT VIDEO | H7: =_xlfn.XLOOKUP(B7&"-00",改定!N:N,改定!E:E) -> 49074 | J7: Stage5対応カメラなし
A8: ○ | B8: 17301-43665 | C8: ディスプレイ | E8: DSD | F8: 5.7"COLOR DISPLAY WITH VIDEO | H8: =_xlfn.XLOOKUP(B8&"-00",改定!N:N,改定!E:E) -> 49074 | J8: Stage5対応カメラあり
A9: ○ | B9: 17301-43666 | C9: ディスプレイ | E9: DSD | F9: 5.7"COLOR DISPLAY WITH VIDEO | H9: =_xlfn.XLOOKUP(B9&"-00",改定!N:N,改定!E:E) -> 43314 | J9: L5E専用コストダウン品
A10: ○ | B10: 07143-00044 | C10: ディスプレイ | E10: DSD | F10: 5.7"COLOR DISPLAY WITH VIDEO | H10: =_xlfn.XLOOKUP(B10&"-00",改定!N:N,改定!E:E) -> 48731 | J10: C10-4専用
B11: 17301-43695 | C11: ディスプレイ | E11: XO | F11: XO-570T | G11: C9-5/C10-5 | H11: =_xlfn.XLOOKUP(B11&"-00",改定!N:N,改定!E:E) -> 62602 | J11: C9-5、C10-5用ディスプレイ
B12: 17301-43667 | C12: ディスプレイ | E12: XO | F12: XO-570T | H12: =_xlfn.XLOOKUP(B12&"-00",改定!N:N,改定!E:E) -> B008955 | J12: ローダー向けディスプレイ
B13: 17301-43671 | C13: ディスプレイ | E13: XO | F13: XO-570TM | H13: =_xlfn.XLOOKUP(B13&"-00",改定!N:N,改定!E:E) -> 63034 | J13: パネル剥がれ防止対策品
B14: 17301-43843 | C14: ディスプレイ | E14: XO | F14: XO-800T | G14: A25H/A27C | H14: =_xlfn.XLOOKUP(B14&"-00",改定!N:N,改定!E:E) -> B009385 | J14: 新規
A15: E | B15: 05542-00024 | C15: コントローラ | D15: メイン | E15: DSD | G15: A12A | H15: =_xlfn.XLOOKUP(B15&"-00",改定!N:N,改定!E:E) -> 40538 | J15: 新規
A16: E | B16: 05542-00114 | C16: コントローラ | D16: メイン | E16: DSD | G16: A12A | H16: =_xlfn.XLOOKUP(B16&"-00",改定!N:N,改定!E:E) -> 46235 | J16: コントローラ切替(MC050-155)
A17: E | B17: 05542-00147 | C17: コントローラ | D17: メイン | E17: DSD | G17: A12A | H17: =_xlfn.XLOOKUP(B17&"-00",改定!N:N,改定!E:E) -> 46656 | J17: イモビライザ追加
A18: ○ | B18: 05542-00326 | C18: コントローラ | D18: メイン | E18: DSD | G18: A12A | H18: =_xlfn.XLOOKUP(B18&"-00",改定!N:N,改定!E:E) -> 49584 | J18: エコモード変更
A19: E | B19: 05542-00173 | C19: コントローラ | D19: メイン | E19: DSD | G19: A13A | H19: =_xlfn.XLOOKUP(B19&"-00",改定!N:N,改定!E:E) -> 48185 | J19: 新規
A20: E | B20: 05542-00411 | C20: コントローラ | D20: メイン | E20: DSD | G20: A13A | H20: =_xlfn.XLOOKUP(B20&"-00",改定!N:N,改定!E:E) -> 52642 | J20: 第2・4サービス同時操作グリップ設定
A21: ○ | B21: 05542-00412 | C21: コントローラ | D21: メイン | E21: DSD | G21: A13A | H21: =_xlfn.XLOOKUP(B21&"-00",改定!N:N,改定!E:E) -> 61312 | J21: EN474:2020対応
A22: E | B22: 05642-00231 | C22: コントローラ | D22: メイン | E22: DSD | G22: A14D-2 | H22: =_xlfn.XLOOKUP(B22&"-00",改定!N:N,改定!E:E) -> 42160 | J22: 新規
A23: ○ | B23: 05642-00371 | C23: コントローラ | D23: メイン | E23: DSD | G23: A14D-2/A14D-3 | H23: =_xlfn.XLOOKUP(B23&"-00",改定!N:N,改定!E:E) -> 45524 | J23: 新規
A24: リリース前 | B24: 05642-00552 | C24: コントローラ | D24: メイン | E24: DSD | G24: A14D-4 | H24: =_xlfn.XLOOKUP(B24&"-00",改定!N:N,改定!E:E) -> 49026 | J24: 新規
A25: E | B25: 05642-65120 | C25: コントローラ | D25: メイン | E25: DSD | G25: A14FW | H25: =_xlfn.XLOOKUP(B25&"-00",改定!N:N,改定!E:E) -> 41019 | J25: メイン新規
A26: E | B26: 05642-00250 | C26: コントローラ | D26: メイン | E26: DSD | G26: A14FW | H26: =_xlfn.XLOOKUP(B26&"-00",改定!N:N,改定!E:E) -> 42834 | J26: コントローラ切替(MC050-155)
... A34: E | B34: 05642-00015 | C34: コントローラ | D34: メイン | E34: DSD | G34: A14H/I | H34: =_xlfn.XLOOKUP(B34&"-00",改定!N:N,改定!E:E) -> 41229 | J34: 新規
A35: E | B35: 05642-00372 | C35: コントローラ | D35: メイン | E35: DSD | G35: A14H/I | H35: =_xlfn.XLOOKUP(B35&"-00",改定!N:N,改定!E:E) -> 46010 | J35: Huppen対応、コントローラ切替(MC050-155) | K35: 3.20受領20180213
A36: E | B36: 05642-00417 | C36: コントローラ | D36: メイン | E36: DSD | G36: A14H/I | H36: =_xlfn.XLOOKUP(B36&"-00",改定!N:N,改定!E:E) -> 46104 | J36: コントローラ切替(MC050-155) | K36: 2.20受領20180213
A37: E | B37: 05642-00483 | C37: コントローラ | D37: メイン | E37: DSD | G37: A14H/I | H37: =_xlfn.XLOOKUP(B37&"-00",改定!N:N,改定!E:E) -> 49650 | J37: Stage5+エコモード
A38: ○ | B38: 05642-00602 | C38: コントローラ | D38: メイン | E38: DSD | G38: A14H/I | H38: =_xlfn.XLOOKUP(B38&"-00",改定!N:N,改定!E:E) -> 51239 | J38: Boschコンバル
A39: 保 | B39: 05642-00455 | C39: コントローラ | D39: メイン | E39: DSD | G39: A14H/I | H39: =_xlfn.XLOOKUP(B39&"-00",改定!N:N,改定!E:E) -> 47366 | J39: ｾﾌﾃｨｽﾀｰﾄ､ｵｰﾄｽﾄｯﾌﾟ無(05642-00372より変更)
A40: 保 | B40: 05642-00456 | C40: コントローラ | D40: メイン | E40: DSD | G40: A14H/I | H40: =_xlfn.XLOOKUP(B40&"-00",改定!N:N,改定!E:E) -> 47366 | J40: ｾﾌﾃｨｽﾀｰﾄ､ｵｰﾄｽﾄｯﾌﾟ無(05642-00417より変更)
A41: 保 | B41: 05642-00573 | C41: コントローラ | D41: メイン | E41: DSD | G41: A14H/I | H41: =_xlfn.XLOOKUP(B41&"-00",改定!N:N,改定!E:E) -> 49853 | J41: Stage5+パワーモード+セフティスタート有
A42: 保 | B42: 05642-00575 | C42: コントローラ | D42: メイン | E42: DSD | G42: A14H/I | H42: =_xlfn.XLOOKUP(B42&"-00",改定!N:N,改定!E:E) -> 49853 | J42: Stage5+パワーモード+セフティスタート無
A43: ○ | B43: 05642-00075 | C43: コントローラ | D43: メイン | E43: DSD | G43: A14I | H43: =_xlfn.XLOOKUP(B43&"-00",改定!N:N,改定!E:E) -> 62636 | I43: V6.xx | J43: エンジンECU変更、機種専用品番番採用
A44: ○ | B44: 05642-00505 | C44: コントローラ | D44: メイン | E44: DSD | G44: A14J | H44: =_xlfn.XLOOKUP(B44&"-00",改定!N:N,改定!E:E) -> 49039 | J44: Stage5対応
A45: ○ | B45: 05642-00606 | C45: コントローラ | D45: メイン | E45: DSD | G45: A14J | H45: =_xlfn.XLOOKUP(B45&"-00",改定!N:N,改定!E:E) -> 51282 | J45: AUX1スプール変更対応
A46: E | B46: 05742-00038 | C46: コントローラ | D46: メイン | E46: DSD | G46: A25E(EU) | H46: =_xlfn.XLOOKUP(B46&"-00",改定!N:N,改定!E:E) -> 42074 | J46: BALSクラスタ
A47: E | B47: 05742-00042 | C47: コントローラ | D47: メイン | E47: DSD | G47: A25E(EU) | H47: =_xlfn.XLOOKUP(B47&"-00",改定!N:N,改定!E:E) -> 42834 | J47: BALSクラスタ
...

Sheet 改定
A1: 機種 | B1: 機種 | C1: 区分 | D1: 名称 | E1: 帳票No | F1: 品番 | G1: Δ | H1: Version | I1: プログラム | J1: パラメータファイル | K1: 設計変更理由 | L1: 備考 | N1: キー | O1: 在庫書き換え -：不要 〇：要 ●：済
A2: E2F | B2: =_xlfn.XLOOKUP(F2,品番!B:B,品番!G:G) -> E2F | C2: =_xlfn.XLOOKUP(F2,品番!B:B,品番!C:C) -> コントローラ | D2: =_xlfn.XLOOKUP(F2,品番!B:B,品番!D:D) -> メイン | E2: 55600 | F2: 03242-00069 | G2: 0 | M2: {=_xlfn.TEXTJOIN(",", TRUE, _xlfn._xlws.FILTER(適用号機!D:D, (適用号機!B:B=改定!F2)*(適用号機!C:C=改定!G2), ""))} -> E2F | N2: =F2 &"-" & TEXT(G2,"00") -> 03242-00069-00 | O2: -
A3: E3F(CBN) | B3: =_xlfn.XLOOKUP(F3,品番!B:B,品番!G:G) -> E3F(CBN) | C3: =_xlfn.XLOOKUP(F3,品番!B:B,品番!C:C) -> コントローラ | D3: =_xlfn.XLOOKUP(F3,品番!B:B,品番!D:D) -> メイン | E3: 60819 | F3: 03342-00130 | G3: 0 | K3: 採番 | M3: {=_xlfn.TEXTJOIN(",", TRUE, _xlfn._xlws.FILTER(適用号機!D:D, (適用号機!B:B=改定!F3)*(適用号機!C:C=改定!G3), ""))} -> E3F | N3: =F3 &"-" & TEXT(G3,"00") -> 03342-00130-00 | O3: -
A4: E3F | B4: =_xlfn.XLOOKUP(F4,品番!B:B,品番!G:G) -> E3F | C4: =_xlfn.XLOOKUP(F4,品番!B:B,品番!C:C) -> コントローラ | D4: =_xlfn.XLOOKUP(F4,品番!B:B,品番!D:D) -> メイン | E4: 49119 | F4: 03342-00163 | G4: 0 | L4: #1~3号機用 | M4: {=_xlfn.TEXTJOIN(",", TRUE, _xlfn._xlws.FILTER(適用号機!D:D, (適用号機!B:B=改定!F4)*(適用号機!C:C=改定!G4), ""))} -> E3F | N4: =F4 &"-" & TEXT(G4,"00") -> 03342-00163-00 | O4: -
A5: E3F | B5: =_xlfn.XLOOKUP(F5,品番!B:B,品番!G:G) -> E3F | C5: =_xlfn.XLOOKUP(F5,品番!B:B,品番!C:C) -> コントローラ | D5: =_xlfn.XLOOKUP(F5,品番!B:B,品番!D:D) -> メイン | E5: 50187 | F5: 03342-00189 | G5: 0 | L5: #4～9号機 | M5: {=_xlfn.TEXTJOIN(",", TRUE, _xlfn._xlws.FILTER(適用号機!D:D, (適用号機!B:B=改定!F5)*(適用号機!C:C=改定!G5), ""))} | N5: =F5 &"-" & TEXT(G5,"00") -> 03342-00189-00 | O5: -
A6: E3F | B6: =_xlfn.XLOOKUP(F6,品番!B:B,品番!G:G) -> E3F | C6: =_xlfn.XLOOKUP(F6,品番!B:B,品番!C:C) -> コントローラ | D6: =_xlfn.XLOOKUP(F6,品番!B:B,品番!D:D) -> メイン | E6: 50187 | F6: 03342-00252 | G6: 0 | L6: 量産仕様 | M6: {=_xlfn.TEXTJOIN(",", TRUE, _xlfn._xlws.FILTER(適用号機!D:D, (適用号機!B:B=改定!F6)*(適用号機!C:C=改定!G6), ""))} -> E3F | N6: =F6 &"-" & TEXT(G6,"00") -> 03342-00252-00 | O6: -
A7: E3F | B7: =_xlfn.XLOOKUP(F7,品番!B:B,品番!G:G) -> E3F | C7: =_xlfn.XLOOKUP(F7,品番!B:B,品番!C:C) -> コントローラ | D7: =_xlfn.XLOOKUP(F7,品番!B:B,品番!D:D) -> メイン | E7: 51443 | F7: 03342-00252 | G7: 1 | M7: {=_xlfn.TEXTJOIN(",", TRUE, _xlfn._xlws.FILTER(適用号機!D:D, (適用号機!B:B=改定!F7)*(適用号機!C:C=改定!G7), ""))} -> E3F | N7: =F7 &"-" & TEXT(G7,"00") -> 03342-00252-01 | O7: -
A8: E3F | B8: =_xlfn.XLOOKUP(F8,品番!B:B,品番!G:G) -> E3F | C8: =_xlfn.XLOOKUP(F8,品番!B:B,品番!C:C) -> コントローラ | D8: =_xlfn.XLOOKUP(F8,品番!B:B,品番!D:D) -> メイン | E8: 51681 | F8: 03342-00252 | G8: 2 | M8: {=_xlfn.TEXTJOIN(",", TRUE, _xlfn._xlws.FILTER(適用号機!D:D, (適用号機!B:B=改定!F8)*(適用号機!C:C=改定!G8), ""))} -> E3F | N8: =F8 &"-" & TEXT(G8,"00") -> 03342-00252-02 | O8: -
A9: E3F | B9: =_xlfn.XLOOKUP(F9,品番!B:B,品番!G:G) -> E3F | C9: =_xlfn.XLOOKUP(F9,品番!B:B,品番!C:C) -> コントローラ | D9: =_xlfn.XLOOKUP(F9,品番!B:B,品番!D:D) -> メイン | E9: 53560 | F9: 03342-00252 | G9: 3 | M9: {=_xlfn.TEXTJOIN(",", TRUE, _xlfn._xlws.FILTER(適用号機!D:D, (適用号機!B:B=改定!F9)*(適用号機!C:C=改定!G9), ""))} -> E3F | N9: =F9 &"-" & TEXT(G9,"00") -> 03342-00252-03 | O9: -
A10: E3F | B10: =_xlfn.XLOOKUP(F10,品番!B:B,品番!G:G) -> E3F | C10: =_xlfn.XLOOKUP(F10,品番!B:B,品番!C:C) -> コントローラ | D10: =_xlfn.XLOOKUP(F10,品番!B:B,品番!D:D) -> メイン | E10: 54076 | F10: 03342-00252 | G10: 4 | M10: {=_xlfn.TEXTJOIN(",", TRUE, _xlfn._xlws.FILTER(適用号機!D:D, (適用号機!B:B=改定!F10)*(適用号機!C:C=改定!G10), ""))} -> E3F | N10: =F10 &"-" & TEXT(G10,"00") -> 03342-00252-04 | O10: -
A11: E3F | B11: =_xlfn.XLOOKUP(F11,品番!B:B,品番!G:G) -> E3F | C11: =_xlfn.XLOOKUP(F11,品番!B:B,品番!C:C) -> コントローラ | D11: =_xlfn.XLOOKUP(F11,品番!B:B,品番!D:D) -> メイン | E11: 54209 | F11: 03342-00252 | G11: 5 | M11: {=_xlfn.TEXTJOIN(",", TRUE, _xlfn._xlws.FILTER(適用号機!D:D, (適用号機!B:B=改定!F11)*(適用号機!C:C=改定!G11), ""))} | N11: =F11 &"-" & TEXT(G11,"00") -> 03342-00252-05 | O11: -
A12: E3F | B12: =_xlfn.XLOOKUP(F12,品番!B:B,品番!G:G) -> E3F | C12: =_xlfn.XLOOKUP(F12,品番!B:B,品番!C:C) -> コントローラ | D12: =_xlfn.XLOOKUP(F12,品番!B:B,品番!D:D) -> メイン | E12: 54603 | F12: 03342-00252 | G12: 6 | M12: {=_xlfn.TEXTJOIN(",", TRUE, _xlfn._xlws.FILTER(適用号機!D:D, (適用号機!B:B=改定!F12)*(適用号機!C:C=改定!G12), ""))} -> E3F, E3F | N12: =F12 &"-" & TEXT(G12,"00") -> 03342-00252-06 | O12: -
A13: E3F | B13: =_xlfn.XLOOKUP(F13,品番!B:B,品番!G:G) -> E3F | C13: =_xlfn.XLOOKUP(F13,品番!B:B,品番!C:C) -> コントローラ | D13: =_xlfn.XLOOKUP(F13,品番!B:B,品番!D:D) -> メイン | E13: 55548 | F13: 03342-00252 | G13: 7 | M13: {=_xlfn.TEXTJOIN(",", TRUE, _xlfn._xlws.FILTER(適用号機!D:D, (適用号機!B:B=改定!F13)*(適用号機!C:C=改定!G13), ""))} -> E3F | N13: =F13 &"-" & TEXT(G13,"00") -> 03342-00252-07 | O13: -
A14: E3F | B14: =_xlfn.XLOOKUP(F14,品番!B:B,品番!G:G) -> E3F | C14: =_xlfn.XLOOKUP(F14,品番!B:B,品番!C:C) -> コントローラ | D14: =_xlfn.XLOOKUP(F14,品番!B:B,品番!D:D) -> メイン | F14: 03342-00515 | G14: 0 | H14: V5.00 | I14: 03396-00025 | L14: 仕様変更：コンバルスプール変更によりパラメータ変更 | M14: {=_xlfn.TEXTJOIN(",", TRUE, _xlfn._xlws.FILTER(適用号機!D:D, (適用号機!B:B=改定!F14)*(適用号機!C:C=改定!G14), ""))} | N14: =F14 &"-" & TEXT(G14,"00") -> 03342-00515-00 | O14: -
A15: E3F | B15: =_xlfn.XLOOKUP(F15,品番!B:B,品番!G:G) -> E3F | C15: =_xlfn.XLOOKUP(F15,品番!B:B,品番!C:C) -> コントローラ | D15: =_xlfn.XLOOKUP(F15,品番!B:B,品番!D:D) -> メイン | F15: 03342-00516 | G15: 0 | H15: V6.00 | I15: 03396-00026 | L15: 仕様変更：コンバルスプール変更によりパラメータ変更 | M15: {=_xlfn.TEXTJOIN(",", TRUE, _xlfn._xlws.FILTER(適用号機!D:D, (適用号機!B:B=改定!F15)*(適用号機!C:C=改定!G15), ""))} | N15: =F15 &"-" & TEXT(G15,"00") -> 03342-00516-00 | O15: -
A16: E3F | B16: =_xlfn.XLOOKUP(F16,品番!B:B,品番!G:G) -> E3F | C16: =_xlfn.XLOOKUP(F16,品番!B:B,品番!C:C) -> コントローラ | D16: =_xlfn.XLOOKUP(F16,品番!B:B,品番!D:D) -> メイン | F16: 03342-00534 | G16: 0 | H16: V7.00 | I16: 03396-00010 | L16: 仕様変更：コンバルスプール変更によりパラメータ変更 | M16: {=_xlfn.TEXTJOIN(",", TRUE, _xlfn._xlws.FILTER(適用号機!D:D, (適用号機!B:B=改定!F16)*(適用号機!C:C=改定!G16), ""))} | N16: =F16 &"-" & TEXT(G16,"00") -> 03342-00534-00 | O16: -
A17: E3F | B17: =_xlfn.XLOOKUP(F17,品番!B:B,品番!G:G) -> E3F | C17: =_xlfn.XLOOKUP(F17,品番!B:B,品番!C:C) -> コントローラ | D17: =_xlfn.XLOOKUP(F17,品番!B:B,品番!D:D) -> メイン | E17: 62888 | F17: 03342-00535 | G17: 0 | H17: V8.00 | I17: 03396-00011 | L17: 仕様変更：コンバルスプール変更によりパラメータ変更 | M17: {=_xlfn.TEXTJOIN(",", TRUE, _xlfn._xlws.FILTER(適用号機!D:D, (適用号機!B:B=改定!F17)*(適用号機!C:C=改定!G17), ""))} -> E3F | N17: =F17 &"-" & TEXT(G17,"00") -> 03342-00535-00 | O17: -
A18: A4E/A4F/J4B | B18: =_xlfn.XLOOKUP(F18,品番!B:B,品番!G:G) -> A4E/A4F/J4B | C18: =_xlfn.XLOOKUP(F18,品番!B:B,品番!C:C) -> コントローラ | D18: =_xlfn.XLOOKUP(F18,品番!B:B,品番!D:D) -> メイン | E18: 46368 | F18: 03442-00020 | G18: 0 | K18: 新規 | L18: スライドSW異常の閾値変更 | M18: {=_xlfn.TEXTJOIN(",", TRUE, _xlfn._xlws.FILTER(適用号機!D:D, (適用号機!B:B=改定!F18)*(適用号機!C:C=改定!G18), ""))} -> A4E | N18: =F18 &"-" & TEXT(G18,"00") -> 03442-00020-00 | O18: -
A19: A4E/A4F/J4B | B19: =_xlfn.XLOOKUP(F19,品番!B:B,品番!G:G) -> A4E/A4F/J4B | C19: =_xlfn.XLOOKUP(F19,品番!B:B,品番!C:C) -> コントローラ | D19: =_xlfn.XLOOKUP(F19,品番!B:B,品番!D:D) -> メイン | E19: 48070 | F19: 03442-00020 | G19: 1 | M19: {=_xlfn.TEXTJOIN(",", TRUE, _xlfn._xlws.FILTER(適用号機!D:D, (適用号機!B:B=改定!F19)*(適用号機!C:C=改定!G19), ""))} -> A4E, A4F | N19: =F19 &"-" & TEXT(G19,"00") -> 03442-00020-01 | O19: -
A20: A4E/A4F/J4B | B20: =_xlfn.XLOOKUP(F20,品番!B:B,品番!G:G) -> A4E/A4F/J4B | C20: =_xlfn.XLOOKUP(F20,品番!B:B,品番!C:C) -> コントローラ | D20: =_xlfn.XLOOKUP(F20,品番!B:B,品番!D:D) -> メイン | E20: 50466 | F20: 03442-00020 | G20: 2 | M20: {=_xlfn.TEXTJOIN(",", TRUE, _xlfn._xlws.FILTER(適用号機!D:D, (適用号機!B:B=改定!F20)*(適用号機!C:C=改定!G20), ""))} | N20: =F20 &"-" & TEXT(G20,"00") -> 03442-00020-02 | O20: -
A21: A4E/A4F/J4B | B21: =_xlfn.XLOOKUP(F21,品番!B:B,品番!G:G) -> A4E/A4F/J4B | C21: =_xlfn.XLOOKUP(F21,品番!B:B,品番!C:C) -> コントローラ | D21: =_xlfn.XLOOKUP(F21,品番!B:B,品番!D:D) -> メイン | E21: 51091 | F21: 03442-00020 | G21: 3 | M21: {=_xlfn.TEXTJOIN(",", TRUE, _xlfn._xlws.FILTER(適用号機!D:D, (適用号機!B:B=改定!F21)*(適用号機!C:C=改定!G21), ""))} -> J4B, A4F,A4E | N21: =F21 &"-" & TEXT(G21,"00") -> 03442-00020-03 | O21: -
A22: A4E/A4F/J4B | B22: =_xlfn.XLOOKUP(F22,品番!B:B,品番!G:G) -> A4E/A4F/J4B | C22: =_xlfn.XLOOKUP(F22,品番!B:B,品番!C:C) -> コントローラ | D22: =_xlfn.XLOOKUP(F22,品番!B:B,品番!D:D) -> メイン | E22: 51447 | F22: 03442-00020 | G22: 4 | M22: {=_xlfn.TEXTJOIN(",", TRUE, _xlfn._xlws.FILTER(適用号機!D:D, (適用号機!B:B=改定!F22)*(適用号機!C:C=改定!G22), ""))} -> J4B, A4F , A4E | N22: =F22 &"-" & TEXT(G22,"00") -> 03442-00020-04 | O22: -
A23: A4E/A4F/J4B | B23: =_xlfn.XLOOKUP(F23,品番!B:B,品番!G:G) -> A4E/A4F/J4B | C23: =_xlfn.XLOOKUP(F23,品番!B:B,品番!C:C) -> コントローラ | D23: =_xlfn.XLOOKUP(F23,品番!B:B,品番!D:D) -> メイン | E23: 52170 | F23: 03442-00020 | G23: 5 | M23: {=_xlfn.TEXTJOIN(",", TRUE, _xlfn._xlws.FILTER(適用号機!D:D, (適用号機!B:B=改定!F23)*(適用号機!C:C=改定!G23), ""))} -> J4B, A4F,A4E | N23: =F23 &"-" & TEXT(G23,"00") -> 03442-00020-05 | O23: -
A24: A4E/A4F/J4B | B24: =_xlfn.XLOOKUP(F24,品番!B:B,品番!G:G) -> A4E/A4F/J4B | C24: =_xlfn.XLOOKUP(F24,品番!B:B,品番!C:C) -> コントローラ | D24: =_xlfn.XLOOKUP(F24,品番!B:B,品番!D:D) -> メイン | E24: 52931 | F24: 03442-00020 | G24: 6 | M24: {=_xlfn.TEXTJOIN(",", TRUE, _xlfn._xlws.FILTER(適用号機!D:D, (適用号機!B:B=改定!F24)*(適用号機!C:C=改定!G24), ""))} -> J4B, A4F, A4E | N24: =F24 &"-" & TEXT(G24,"00") -> 03442-00020-06 | O24: -
A25: A4E/A4F/J4B | B25: =_xlfn.XLOOKUP(F25,品番!B:B,品番!G:G) -> A4E/A4F/J4B | C25: =_xlfn.XLOOKUP(F25,品番!B:B,品番!C:C) -> コントローラ | D25: =_xlfn.XLOOKUP(F25,品番!B:B,品番!D:D) -> メイン | E25: 53099 | F25: 03442-00020 | G25: 7 | M25: {=_xlfn.TEXTJOIN(",", TRUE, _xlfn._xlws.FILTER(適用号機!D:D, (適用号機!B:B=改定!F25)*(適用号機!C:C=改定!G25), ""))} -> J4B, A4F, A4E | N25: =F25 &"-" & TEXT(G25,"00") -> 03442-00020-07 | O25: -
A26: A4E/A4F/J4B | B26: =_xlfn.XLOOKUP(F26,品番!B:B,品番!G:G) -> A4E/A4F/J4B | C26: =_xlfn.XLOOKUP(F26,品番!B:B,品番!C:C) -> コントローラ | D26: =_xlfn.XLOOKUP(F26,品番!B:B,品番!D:D) -> メイン | E26: 54464 | F26: 03442-00020 | G26: 8 | H26: V1.19 | K26: 不具合修正：スライドスイッチ中立条件 | M26: {=_xlfn.TEXTJOIN(",", TRUE, _xlfn._xlws.FILTER(適用号機!D:D, (適用号機!B:B=改定!F26)*(適用号機!C:C=改定!G26), ""))} -> A4F | N26: =F26 &"-" & TEXT(G26,"00") -> 03442-00020-08 | O26: -
A27: A4E/A4F/J4B | B27: =_xlfn.XLOOKUP(F27,品番!B:B,品番!G:G) -> A4E/A4F/J4B | C27: =_xlfn.XLOOKUP(F27,品番!B:B,品番!C:C) -> コントローラ | D27: =_xlfn.XLOOKUP(F27,品番!B:B,品番!D:D) -> メイン | E27: 55511 | F27: 03442-00020 | G27: 9 | H27: V1.20 | I27: - | J27: - | M27: {=_xlfn.TEXTJOIN(",", TRUE, _xlfn._xlws.FILTER(適用号機!D:D, (適用号機!B:B=改定!F27)*(適用号機!C:C=改定!G27), ""))} -> J4B, A4F,A4E | N27: =F27 &"-" & TEXT(G27,"00") -> 03442-00020-09 | O27: -
A28: A4E/A4F/J4B | B28: =_xlfn.XLOOKUP(F28,品番!B:B,品番!G:G) -> A4E/A4F/J4B | C28: =_xlfn.XLOOKUP(F28,品番!B:B,品番!C:C) -> コントローラ | D28: =_xlfn.XLOOKUP(F28,品番!B:B,品番!D:D) -> メイン | E28: 53559 | F28: 03442-00195 | G28: 0 | K28: クレーンタイプ | L28: クレーン仕様 | M28: {=_xlfn.TEXTJOIN(",", TRUE, _xlfn._xlws.FILTER(適用号機!D:D, (適用号機!B:B=改定!F28)*(適用号機!C:C=改定!G28), ""))} -> J4B | N28: =F28 &"-" & TEXT(G28,"00") -> 03442-00195-00 | O28: -
A29: A4E/A4F/J4B | B29: =_xlfn.XLOOKUP(F29,品番!B:B,品番!G:G) -> A4E/A4F/J4B | C29: =_xlfn.XLOOKUP(F29,品番!B:B,品番!C:C) -> コントローラ | D29: =_xlfn.XLOOKUP(F29,品番!B:B,品番!D:D) -> メイン | E29: 53774 | F29: 03442-00195 | G29: 1 | M29: {=_xlfn.TEXTJOIN(",", TRUE, _xlfn._xlws.FILTER(適用号機!D:D, (適用号機!B:B=改定!F29)*(適用号機!C:C=改定!G29), ""))} -> J4B | N29: =F29 &"-" & TEXT(G29,"00") -> 03442-00195-01 | O29: -
A30: A4E/A4F/J4B | B30: =_xlfn.XLOOKUP(F30,品番!B:B,品番!G:G) -> A4E/A4F/J4B | C30: =_xlfn.XLOOKUP(F30,品番!B:B,品番!C:C) -> コントローラ | D30: =_xlfn.XLOOKUP(F30,品番!B:B,品番!D:D) -> メイン | E30: 54251 | F30: 03442-00195 | G30: 2 | M30: {=_xlfn.TEXTJOIN(",", TRUE, _xlfn._xlws.FILTER(適用号機!D:D, (適用号機!B:B=改定!F30)*(適用号機!C:C=改定!G30), ""))} -> J4B | N30: =F30 &"-" & TEXT(G30,"00") -> 03442-00195-02 | O30: -
A31: A4E/A4F/J4B | B31: =_xlfn.XLOOKUP(F31,品番!B:B,品番!G:G) -> A4E/A4F/J4B | C31: =_xlfn.XLOOKUP(F31,品番!B:B,品番!C:C) -> コントローラ | D31: =_xlfn.XLOOKUP(F31,品番!B:B,品番!D:D) -> メイン | E31: 54353 | F31: 03442-00195 | G31: 3 | M31: {=_xlfn.TEXTJOIN(",", TRUE, _xlfn._xlws.FILTER(適用号機!D:D, (適用号機!B:B=改定!F31)*(適用号機!C:C=改定!G31), ""))} -> J4B | N31: =F31 &"-" & TEXT(G31,"00") -> 03442-00195-03 | O31: -
A32: A4E/A4F/J4B | B32: =_xlfn.XLOOKUP(F32,品番!B:B,品番!G:G) -> A4E/A4F/J4B | C32: =_xlfn.XLOOKUP(F32,品番!B:B,品番!C:C) -> コントローラ | D32: =_xlfn.XLOOKUP(F32,品番!B:B,品番!D:D) -> メイン | E32: 54464 | F32: 03442-00195 | G32: 4 | H32: V2.05 | K32: 不具合修正：スライドスイッチ中立条件 | M32: {=_xlfn.TEXTJOIN(",", TRUE, _xlfn._xlws.FILTER(適用号機!D:D, (適用号機!B:B=改定!F32)*(適用号機!C:C=改定!G32), ""))} -> J4B | N32: =F32 &"-" & TEXT(G32,"00") -> 03442-00195-04 | O32: -
A33: A4E/A4F/J4B | B33: =_xlfn.XLOOKUP(F33,品番!B:B,品番!G:G) -> A4E/A4F/J4B | C33: =_xlfn.XLOOKUP(F33,品番!B:B,品番!C:C) -> コントローラ | D33: =_xlfn.XLOOKUP(F33,品番!B:B,品番!D:D) -> メイン | E33: 55511 | F33: 03442-00195 | G33: 5 | H33: V2.06 | I33: - | J33: - | M33: {=_xlfn.TEXTJOIN(",", TRUE, _xlfn._xlws.FILTER(適用号機!D:D, (適用号機!B:B=改定!F33)*(適用号機!C:C=改定!G33), ""))} -> J4B | N33: =F33 &"-" & TEXT(G33,"00") -> 03442-00195-05 | O33: -
A34: A5F,A7FG,A12B | B34: =_xlfn.XLOOKUP(F34,品番!B:B,品番!G:G) -> A5F,A7FG,A12B | C34: =_xlfn.XLOOKUP(F34,品番!B:B,品番!C:C) -> コントローラ | D34: =_xlfn.XLOOKUP(F34,品番!B:B,品番!D:D) -> メイン | E34: 42121 | F34: 03542-00020 | G34: 0 | K34: ディスプレイのモデルチェンジ | L34: スライドSW異常の閾値変更 | M34: {=_xlfn.TEXTJOIN(",", TRUE, _xlfn._xlws.FILTER(適用号機!D:D, (適用号機!B:B=改定!F34)*(適用号機!C:C=改定!G34), ""))} | N34: =F34 &"-" & TEXT(G34,"00") -> 03542-00020-00 | O34: -
A35: A5F,A7FG,A12B | B35: =_xlfn.XLOOKUP(F35,品番!B:B,品番!G:G) -> A5F,A7FG,A12B | C35: =_xlfn.XLOOKUP(F35,品番!B:B,品番!C:C) -> コントローラ | D35: =_xlfn.XLOOKUP(F35,品番!B:B,品番!D:D) -> メイン | E35: 42644 | F35: 03542-00020 | G35: 1 | M35: {=_xlfn.TEXTJOIN(",", TRUE, _xlfn._xlws.FILTER(適用号機!D:D, (適用号機!B:B=改定!F35)*(適用号機!C:C=改定!G35), ""))} | N35: =F35 &"-" & TEXT(G35,"00") -> 03542-00020-01 | O35: -
A36: A5F,A7FG,A12B | B36: =_xlfn.XLOOKUP(F36,品番!B:B,品番!G:G) -> A5F,A7FG,A12B | C36: =_xlfn.XLOOKUP(F36,品番!B:B,品番!C:C) -> コントローラ | D36: =_xlfn.XLOOKUP(F36,品番!B:B,品番!D:D) -> メイン | E36: 42988 | F36: 03542-00020 | G36: 2 | M36: {=_xlfn.TEXTJOIN(",", TRUE, _xlfn._xlws.FILTER(適用号機!D:D, (適用号機!B:B=改定!F36)*(適用号機!C:C=改定!G36), ""))} -> A5F,A7F | N36: =F36 &"-" & TEXT(G36,"00") -> 03542-00020-02 | O36: -
A37: A5F,A7FG,A12B | B37: =_xlfn.XLOOKUP(F37,品番!B:B,品番!G:G) -> A5F,A7FG,A12B | C37: =_xlfn.XLOOKUP(F37,品番!B:B,品番!C:C) -> コントローラ | D37: =_xlfn.XLOOKUP(F37,品番!B:B,品番!D:D) -> メイン | E37: 43589 | F37: 03542-00020 | G37: 3 | M37: {=_xlfn.TEXTJOIN(",", TRUE, _xlfn._xlws.FILTER(適用号機!D:D, (適用号機!B:B=改定!F37)*(適用号機!C:C=改定!G37), ""))} -> A5F,A7F | N37: =F37 &"-" & TEXT(G37,"00") -> 03542-00020-03 | O37: -
A38: A5F,A7FG,A12B | B38: =_xlfn.XLOOKUP(F38,品番!B:B,品番!G:G) -> A5F,A7FG,A12B | C38: =_xlfn.XLOOKUP(F38,品番!B:B,品番!C:C) -> コントローラ | D38: =_xlfn.XLOOKUP(F38,品番!B:B,品番!D:D) -> メイン | E38: 43748 | F38: 03542-00020 | G38: 4 | M38: {=_xlfn.TEXTJOIN(",", TRUE, _xlfn._xlws.FILTER(適用号機!D:D, (適用号機!B:B=改定!F38)*(適用号機!C:C=改定!G38), ""))} -> A5F,A7F | N38: =F38 &"-" & TEXT(G38,"00") -> 03542-00020-04 | O38: -
A39: A5F,A7FG,A12B | B39: =_xlfn.XLOOKUP(F39,品番!B:B,品番!G:G) -> A5F,A7FG,A12B | C39: =_xlfn.XLOOKUP(F39,品番!B:B,品番!C:C) -> コントローラ | D39: =_xlfn.XLOOKUP(F39,品番!B:B,品番!D:D) -> メイン | E39: 46167 | F39: 03542-00020 | G39: 5 | M39: {=_xlfn.TEXTJOIN(",", TRUE, _xlfn._xlws.FILTER(適用号機!D:D, (適用号機!B:B=改定!F39)*(適用号機!C:C=改定!G39), ""))} -> A6E, A7F, A5F, A7G,A12B | N39: =F39 &"-" & TEXT(G39,"00") -> 03542-00020-05 | O39: -
A40: A5F,A7FG,A12B | B40: =_xlfn.XLOOKUP(F40,品番!B:B,品番!G:G) -> A5F,A7FG,A12B | C40: =_xlfn.XLOOKUP(F40,品番!B:B,品番!C:C) -> コントローラ | D40: =_xlfn.XLOOKUP(F40,品番!B:B,品番!D:D) -> メイン | E40: 46629 | F40: 03542-00020 | G40: 6 | M40: {=_xlfn.TEXTJOIN(",", TRUE, _xlfn._xlws.FILTER(適用号機!D:D, (適用号機!B:B=改定!F40)*(適用号機!C:C=改定!G40), ""))} -> A6E,A7F,A5F,A7G,A5F,A12B | N40: =F40 &"-" & TEXT(G40,"00") -> 03542-00020-06 | O40: -
...

Sheet Sheet2
A1: A列 | B1: B列 | C1: =COUNTIFS($A$2:$A$7,$A1,$B$2:$B$7,$B1)>1 -> FALSE
A2: A | B2: 10 | C2: =COUNTIFS($A$2:$A$7,$A2,$B$2:$B$7,$B2)>1 -> FALSE
A3: A | B3: 11 | C3: =COUNTIFS($A$2:$A$7,$A3,$B$2:$B$7,$B3)>1 -> TRUE
A4: B | B4: 1 | C4: =COUNTIFS($A$2:$A$7,$A4,$B$2:$B$7,$B4)>1 -> FALSE
A5: B | B5: 2 | C5: =COUNTIFS($A$2:$A$7,$A5,$B$2:$B$7,$B5)>1 -> FALSE
A6: B | B6: 3 | C6: =COUNTIFS($A$2:$A$7,$A6,$B$2:$B$7,$B6)>1 -> FALSE
A7: A | B7: 11 | C7: =COUNTIFS($A$2:$A$7,$A7,$B$2:$B$7,$B7)>1 -> TRUE

Sheet 適用号機
A1: 設変 | B1: 品番 | C1: Δ | D1: 機種 | E1: 予定 | F1: 実施 | G1: 区分 | H1: 備考
A2: =_xlfn.XLOOKUP(B2 & "-" & TEXT(C2,"00"),改定!N:N,改定!E:E) -> 33269 | B2: 05642-57920 | C2: 0 | D2: A14D-1 | E2: 1213 | F2: 0
A3: =_xlfn.XLOOKUP(B3 & "-" & TEXT(C3,"00"),改定!N:N,改定!E:E) -> 33390 | B3: 06942-05320 | C3: 0 | D3: L9C | E3: 3 | F3: 0
A4: =_xlfn.XLOOKUP(B4 & "-" & TEXT(C4,"00"),改定!N:N,改定!E:E) -> 33453 | B4: 05642-57920 | C4: 1 | D4: A11D | E4: -1 | F4: 0
A5: =_xlfn.XLOOKUP(B5 & "-" & TEXT(C5,"00"),改定!N:N,改定!E:E) -> 33453 | B5: 05642-57920 | C5: 1 | D5: A14D-1 | E5: -1 | F5: 0
A6: =_xlfn.XLOOKUP(B6 & "-" & TEXT(C6,"00"),改定!N:N,改定!E:E) -> 33453 | B6: 05642-57920 | C6: 1 | D6: A25D | E6: -1 | F6: 0
A7: =_xlfn.XLOOKUP(B7 & "-" & TEXT(C7,"00"),改定!N:N,改定!E:E) -> 33453 | B7: 05642-57920 | C7: 1 | D7: A9D | E7: -1 | F7: 0
A8: =_xlfn.XLOOKUP(B8 & "-" & TEXT(C8,"00"),改定!N:N,改定!E:E) -> 33457 | B8: 17301-43650 | C8: 0 | D8: A12A | E8: 1 | F8: 0
A9: =_xlfn.XLOOKUP(B9 & "-" & TEXT(C9,"00"),改定!N:N,改定!E:E) -> 33457 | B9: 17301-43650 | C9: 0 | D9: A12B | E9: 1 | F9: 0
A10: =_xlfn.XLOOKUP(B10 & "-" & TEXT(C10,"00"),改定!N:N,改定!E:E) -> 33631 | B10: 06942-05320 | C10: 1 | D10: L8C | E10: 2 | F10: 0
A11: =_xlfn.XLOOKUP(B11 & "-" & TEXT(C11,"00"),改定!N:N,改定!E:E) -> 33631 | B11: 06942-05320 | C11: 1 | D11: L9C | E11: 3 | F11: 0
A12: =_xlfn.XLOOKUP(B12 & "-" & TEXT(C12,"00"),改定!N:N,改定!E:E) -> 40000 | B12: 05742-06450 | C12: 0 | D12: A25E | E12: 2
A13: =_xlfn.XLOOKUP(B13 & "-" & TEXT(C13,"00"),改定!N:N,改定!E:E) -> 40000 | B13: 05742-06450 | C13: 0 | D13: A25EW | E13: 2
A14: =_xlfn.XLOOKUP(B14 & "-" & TEXT(C14,"00"),改定!N:N,改定!E:E) -> 40004 | B14: 06942-05320 | C14: 2 | D14: L8C | E14: 3
A15: =_xlfn.XLOOKUP(B15 & "-" & TEXT(C15,"00"),改定!N:N,改定!E:E) -> 40004 | B15: 06942-05320 | C15: 2 | D15: L9C | E15: 4
A16: =_xlfn.XLOOKUP(B16 & "-" & TEXT(C16,"00"),改定!N:N,改定!E:E) -> 40059 | B16: 05642-57920 | C16: 2 | D16: A11D | E16: -
A17: =_xlfn.XLOOKUP(B17 & "-" & TEXT(C17,"00"),改定!N:N,改定!E:E) -> 40059 | B17: 05642-57920 | C17: 2 | D17: A14D-1 | E17: -
A18: =_xlfn.XLOOKUP(B18 & "-" & TEXT(C18,"00"),改定!N:N,改定!E:E) -> 40059 | B18: 05642-57920 | C18: 2 | D18: A25D | E18: -
A19: =_xlfn.XLOOKUP(B19 & "-" & TEXT(C19,"00"),改定!N:N,改定!E:E) -> 40059 | B19: 05642-57920 | C19: 2 | D19: A9D | E19: -
A20: =_xlfn.XLOOKUP(B20 & "-" & TEXT(C20,"00"),改定!N:N,改定!E:E) -> 40088 | B20: 06942-05320 | C20: 3 | D20: L8C | E20: -
A21: =_xlfn.XLOOKUP(B21 & "-" & TEXT(C21,"00"),改定!N:N,改定!E:E) -> 40088 | B21: 06942-05320 | C21: 3 | D21: L9C | E21: -
A22: =_xlfn.XLOOKUP(B22 & "-" & TEXT(C22,"00"),改定!N:N,改定!E:E) -> 40151 | B22: 06942-05320 | C22: 4 | D22: L8C | E22: 2
A23: =_xlfn.XLOOKUP(B23 & "-" & TEXT(C23,"00"),改定!N:N,改定!E:E) -> 40151 | B23: 06942-05320 | C23: 4 | D23: L9C | E23: 3
A24: =_xlfn.XLOOKUP(B24 & "-" & TEXT(C24,"00"),改定!N:N,改定!E:E) -> 40194 | B24: 06942-05320 | C24: 5 | D24: L8C | E24: 87
A25: =_xlfn.XLOOKUP(B25 & "-" & TEXT(C25,"00"),改定!N:N,改定!E:E) -> 40194 | B25: 06942-05320 | C25: 5 | D25: L9C | E25: 4
A26: =_xlfn.XLOOKUP(B26 & "-" & TEXT(C26,"00"),改定!N:N,改定!E:E) -> 40250 | B26: 06942-05320 | C26: 6 | D26: L6E | E26: 1
A27: =_xlfn.XLOOKUP(B27 & "-" & TEXT(C27,"00"),改定!N:N,改定!E:E) -> 40250 | B27: 06942-05320 | C27: 6 | D27: L8C | E27: 242
A28: =_xlfn.XLOOKUP(B28 & "-" & TEXT(C28,"00"),改定!N:N,改定!E:E) -> 40250 | B28: 06942-05320 | C28: 6 | D28: L9C | E28: 100
A29: =_xlfn.XLOOKUP(B29 & "-" & TEXT(C29,"00"),改定!N:N,改定!E:E) -> 40311 | B29: 05742-06450 | C29: 1 | D29: A25E | E29: 3
A30: =_xlfn.XLOOKUP(B30 & "-" & TEXT(C30,"00"),改定!N:N,改定!E:E) -> 40385 | B30: 05742-06450 | C30: 2 | D30: A25E | E30: 5
A31: =_xlfn.XLOOKUP(B31 & "-" & TEXT(C31,"00"),改定!N:N,改定!E:E) -> 40415 | B31: 05742-06450 | C31: 3 | D31: A25E | E31: 2
A32: =_xlfn.XLOOKUP(B32 & "-" & TEXT(C32,"00"),改定!N:N,改定!E:E) -> 40416 | B32: 06942-05320 | C32: 7 | D32: L6E | E32: 2
A33: =_xlfn.XLOOKUP(B33 & "-" & TEXT(C33,"00"),改定!N:N,改定!E:E) -> 40416 | B33: 06942-05320 | C33: 7 | D33: L8C | E33: 368
... A39: =_xlfn.XLOOKUP(B39 & "-" & TEXT(C39,"00"),改定!N:N,改定!E:E) -> 40677 | B39: 05542-00024 | C39: 1 | D39: A12B | E39: 3
A40: =_xlfn.XLOOKUP(B40 & "-" & TEXT(C40,"00"),改定!N:N,改定!E:E) -> 40708 | B40: 05742-06450 | C40: 5 | D40: A25E | E40: -
A41: =_xlfn.XLOOKUP(B41 & "-" & TEXT(C41,"00"),改定!N:N,改定!E:E) -> 40708 | B41: 06942-05320 | C41: 8 | D41: L6E | E41: -
A42: =_xlfn.XLOOKUP(B42 & "-" & TEXT(C42,"00"),改定!N:N,改定!E:E) -> 40708 | B42: 06942-05320 | C42: 8 | D42: L8C | E42: -
A43: =_xlfn.XLOOKUP(B43 & "-" & TEXT(C43,"00"),改定!N:N,改定!E:E) -> 40708 | B43: 06942-05320 | C43: 8 | D43: L9C | E43: -
A44: =_xlfn.XLOOKUP(B44 & "-" & TEXT(C44,"00"),改定!N:N,改定!E:E) -> 41019 | B44: 05642-65120 | C44: 0 | D44: A14FW | E44: 3
A45: =_xlfn.XLOOKUP(B45 & "-" & TEXT(C45,"00"),改定!N:N,改定!E:E) -> 41043 | B45: 05542-00024 | C45: 2 | D45: A12A | E45: 2
...

Sheet テーブル2
A1: 帳票番号 | B1: 商品結合
A2: 1 | B2: A,B,C,D
A3: 2 | B3: A,B,C
A4: 3 | B4: A
A5: 4 | B5: B,C
A6: 5 | B6: A
A7: 6 | B7: C

Sheet Sheet1
A1: 帳票番号 | B1: 商品 | C1: 数量
A2: 001 | B2: A | C2: 50 | D2: {=_xlfn.UNIQUE(A2:A14)} -> 001 | E2: {=_xlfn.TEXTJOIN(",",TRUE,IF(A:A=D2,B:B,""))} -> A,B,C,D,A,B,C,D
A3: 001 | B3: B | C3: 80 | D3: 002 | E3: {=_xlfn.TEXTJOIN(",",TRUE,IF(A:A=D3,B:B,""))} -> A,B,C,A,B,C
A4: 001 | B4: C | C4: 1 | D4: 003 | E4: {=_xlfn.TEXTJOIN(",",TRUE,IF(A:A=D4,B:B,""))} -> A,A
A5: 001 | B5: D | C5: 1 | D5: 004 | E5: {=_xlfn.TEXTJOIN(",",TRUE,IF(A:A=D5,B:B,""))} -> B,C,B,C | G5: {=_xlfn.IFS(ture,TRUE)} -> #NAME?
A6: 002 | B6: A | C6: 80 | D6: 005 | E6: {=_xlfn.TEXTJOIN(",",TRUE,IF(A:A=D6,B:B,""))} -> A,A
A7: 002 | B7: B | C7: 80 | D7: 006 | E7: {=_xlfn.TEXTJOIN(",",TRUE,IF(A:A=D7,B:B,""))} -> C,C
A8: 002 | B8: C | C8: 1 | D8: 0
A9: 003 | B9: A | C9: 50
A10: 004 | B10: B | C10: 120
A11: 004 | B11: C | C11: 1
A12: 005 | B12: A | C12: 60
A13: 006 | B13: C | C13: 10
A22: 帳票番号 | B22: 商品 | J22: 品番 | K22: 分類 | L22: 名称 | N22: 品番 | O22: 分類 | P22: 名称一覧
A23: 001 | B23: A | J23: 001 | K23: 1 | L23: A | N23: 001 | O23: 1 | P23: {=_xlfn.TEXTJOIN(",", TRUE, _xlfn._xlws.FILTER(適用号機!D:D, (適用号機!B:B=改定!F782)*(適用号機!C:C=改定!G782), ""))} -> L5E,L5E2,L6F,L8EV,L8EV2,L9ER,L9ER2,L9EV,L9EV2
A24: 001 | B24: B | J24: 001 | K24: 1 | L24: B | N24: 001 | O24: 2 | P24: {=_xlfn.TEXTJOIN(",", TRUE, _xlfn._xlws.FILTER(L24:L36, (J24:J36=N24)*(K24:K36=O24), ""))} -> A,B
A25: 001 | B25: C | J25: 001 | K25: 1 | L25: C | N25: 001 | O25: 3 | P25: {=_xlfn.TEXTJOIN(",", TRUE, _xlfn._xlws.FILTER(L25:L37, (J25:J37=N25)*(K25:K37=O25), ""))} -> D,A,B
A26: 001 | B26: D | J26: 001 | K26: 2 | L26: A | N26: 002 | O26: 1 | P26: {=_xlfn.TEXTJOIN(",", TRUE, _xlfn._xlws.FILTER(L26:L38, (J26:J38=N26)*(K26:K38=O26), ""))} -> B
A27: 002 | B27: A | J27: 001 | K27: 2 | L27: B | N27: 002 | O27: 2 | P27: {=_xlfn.TEXTJOIN(",", TRUE, _xlfn._xlws.FILTER(L27:L39, (J27:J39=N27)*(K27:K39=O27), ""))} -> C,D
A28: 002 | B28: B | J28: 001 | K28: 3 | L28: D | N28: 002 | O28: 3 | P28: {=_xlfn.TEXTJOIN(",", TRUE, _xlfn._xlws.FILTER(L28:L40, (J28:J40=N28)*(K28:K40=O28), ""))} -> D,A
A29: 002 | B29: C | J29: 001 | K29: 3 | L29: A
A30: 003 | B30: A | J30: 001 | K30: 3 | L30: B
A31: 004 | B31: B | J31: 002 | K31: 1 | L31: B
A32: 004 | B32: C | J32: 002 | K32: 2 | L32: C
A33: 005 | B33: A | J33: 002 | K33: 2 | L33: D
A34: 006 | B34: C | J34: 002 | K34: 3 | L34: D
J35: 002 | K35: 3 | L35: A

Sheet d30
C1: プログラムなしタイプ
B2: Active | C2: TES品番 | D2: コントローラ型番 | H2: 名称 | I2: ＣＡＮ | J2: 入力 | K2: 出力
B3: E | C3: 17301-43310 | D3: MC050-010 | H3: 50Pコントローラ | I3: 2 | J3: 20 | K3: 16
B4: ○ | C4: 17301-43311 | D4: MC050-110 | H4: 50Pコントローラ | I4: 2 | J4: 20 | K4: 16
B5: E | C5: 17301-43320 | D5: DP200-01-01-03 | H5: DP200ディスプレイ | I5: 1 | J5: 6 | K5: 1
B6: ○ | C6: 17301-43330 | D6: IX024-010 | H6: 24P入力拡張モジュール | I6: 1 | J6: 17 | K6: 0
B7: E | C7: 17301-43340 | D7: OX024-010 | H7: 24P出力拡張モジュール | I7: 1 | J7: 0 | K7: 16
B8: ○ | C8: 17301-43341 | D8: OX024-110 | H8: 24P出力拡張モジュール | I8: 1 | J8: 0 | K8: 16
B9: ○ | C9: 17301-43342 | D9: OX024-110 | H9: 24P出力拡張モジュール(500kbps) | I9: 1 | J9: 0 | K9: 16
B10: ○ | C10: 17301-43350 | D10: DP250-01-01-04-05 | H10: DP250カラーディスプレイ | I10: 1 | J10: 6 | K10: 1
B11: E | C11: 17301-43360 | D11: MC050-055 | H11: 50Pコントローラ055 | I11: 3 | J11: 33 | K11: 3
B12: ○ | C12: 17301-43361 | D12: MC050-155 | H12: 50Pコントローラ155 | I12: 3 | J12: 33 | K12: 3
B13: ○ | C13: 17301-43370 | D13: ＩＸ012-010 | H13: 12P入力拡張モジュール | I13: 1 | J13: 5 | K13: 0
B14: E | C14: 17301-43380 | D14: OX012-010 | H14: 12P出力拡張モジュール | I14: 1 | J14: 0 | K14: 6
... B38: ○ | C38: 17301-43770 | D38: SC024-110 | H38: 24Pコントローラ | I38: 1 | J38: 13 | K38: 4
C39: 17301-43730 | D39: IOX012-010 | H39: 12P入出力拡張モジュール | I39: 1 | J39: 3 | K39: 2
B40: E | C40: 17301-43740 | D40: IOX024-020 | H40: 24P入出力拡張モジュール | I40: 1 | J40: 7 | K40: 8
B41: ○ | C41: 17301-43741 | D41: IOX024-120 | H41: 24P入出力拡張モジュール | I41: 1 | J41: 7 | K41: 8
B42: ○ | C42: 17301-43742 | D42: IOX024-120 | H42: 24P入出力拡張モジュール(500kbps) | I42: 1 | J42: 7 | K42: 8
B43: ○ | C43: 17301-43760 | D43: OX024-110 | H43: リレー駆動用モジュール(500kbps) | I43: 1 | J43: 0 | K43: 16
C44: 17301-43510 | D44: GPSキット | H44: WS-403
B45: ○ | C45: 17301-43470 | D45: XL104-0019(Large) | I45: 3 | J45: 31 | K45: 33
B46: ○ | C46: 17301-43480 | D46: XL104-0029(Small) | I46: 3 | J46: 40 | K46: 24
B47: - | C47: 17301-43490 | D47: XL104-0000(Full) | I47: 3 | J47: 48 | K47: 40
B48: ○ | C48: 17301-43580 | D48: SC050-120 | H48: 50PSafty
C49: 赤字：ＥＣＡＤシンボル有
C50: コントローラを組立図の部品表のせるときには、品番：機種品番、品名：コントローラAssyとして登録してください。コントローラAssyの子部品は、コントローラ（プログラムなし）+メインプログラム+パラメータファイルが入ります。
D52: メインプログラム
B53: Active | C53: 機種 | D53: コントローラ品番(ASSY) | E53: Version | F53: 帳票No | G53: Δ | H53: PLUS1(プログラムなし） | I53: プログラム | J53: パラメータファイル | K53: 備考 | L53: SN | M53: SN2 | N53: SN3 | O53: SN4 | P53: 設計変更理由 | Q53: PSW | R53: Application ID
B54: ○ | C54: 共通 | D54: 17301-44340 | H54: 17301-43350(DP250) | I54: - | J54: - | Q54: -
B55: E | C55: 5.7'ディスプレイ | D55: 17301-43650 | E55: 1.7 | H55: - | I55: - | J55: - | K55: カメラなし | Q55: 1.7
B56: E | D56: 17301-43651 | E56: 1.7 | H56: - | I56: - | J56: - | K56: カメラあり | Q56: 1.4
B57: E | D57: 17301-43660 | E57: 1.33 | H57: - | I57: - | J57: - | K57: カメラなし | Q57: 1.33
B58: E | D58: 17301-43661 | E58: 1.33 | H58: - | I58: - | J58: - | K58: カメラあり | Q58: 1.33
B59: ○ | D59: 17301-43664 | E59: 1.65 | H59: - | I59: - | J59: - | K59: Stage5対応カメラなし | Q59: 1.5
B60: ○ | D60: 17301-43665 | E60: 1.65 | H60: - | I60: - | J60: - | K60: Stage5対応カメラあり | Q60: 1.5
B61: ○ | D61: 17301-43666 | E61: 1.65 | H61: - | I61: - | J61: - | K61: L5E専用コストダウン品 | Q61: 1.5
B62: ○ | D62: 07143-00044 | E62: 1 | H62: - | K62: C10-4専用
B63: E | C63: A12A | D63: 05542-00024 | E63: V1.09 | F63: 55511 | G63: 9 | H63: 17301-43360(MC050-055) | I63: 05542-00026_09 | J63: 05542_00027_09 | K63: 新規 | L63: 126000002~126002171 | P63: 新規 | Q63: 1.06
B64: E | D64: 05542-00114 | E64: V2.12 | F64: 55511 | G64: 4 | H64: 17301-43361(MC050-155) | I64: - | J64: 0554200114v212 | K64: コントローラ切替(MC050-155) | L64: 126002172~126002489 | P64: ディスプレイのモデルチェンジ | Q64: 2.01
...

Sheet d29
C1: プログラムなしタイプ
B2: Active | C2: TES品番 | D2: コントローラ型番 | H2: 名称 | I2: ＣＡＮ | J2: 入力 | K2: 出力
B3: E | C3: 17301-43310 | D3: MC050-010 | H3: 50Pコントローラ | I3: 2 | J3: 20 | K3: 16
B4: ○ | C4: 17301-43311 | D4: MC050-110 | H4: 50Pコントローラ | I4: 2 | J4: 20 | K4: 16
B5: E | C5: 17301-43320 | D5: DP200-01-01-03 | H5: DP200ディスプレイ | I5: 1 | J5: 6 | K5: 1
B6: ○ | C6: 17301-43330 | D6: IX024-010 | H6: 24P入力拡張モジュール | I6: 1 | J6: 17 | K6: 0
B7: E | C7: 17301-43340 | D7: OX024-010 | H7: 24P出力拡張モジュール | I7: 1 | J7: 0 | K7: 16
B8: ○ | C8: 17301-43341 | D8: OX024-110 | H8: 24P出力拡張モジュール | I8: 1 | J8: 0 | K8: 16
B9: ○ | C9: 17301-43342 | D9: OX024-110 | H9: 24P出力拡張モジュール(500kbps) | I9: 1 | J9: 0 | K9: 16
B10: ○ | C10: 17301-43350 | D10: DP250-01-01-04-05 | H10: DP250カラーディスプレイ | I10: 1 | J10: 6 | K10: 1
B11: E | C11: 17301-43360 | D11: MC050-055 | H11: 50Pコントローラ055 | I11: 3 | J11: 33 | K11: 3
B12: ○ | C12: 17301-43361 | D12: MC050-155 | H12: 50Pコントローラ155 | I12: 3 | J12: 33 | K12: 3
B13: ○ | C13: 17301-43370 | D13: ＩＸ012-010 | H13: 12P入力拡張モジュール | I13: 1 | J13: 5 | K13: 0
B14: E | C14: 17301-43380 | D14: OX012-010 | H14: 12P出力拡張モジュール | I14: 1 | J14: 0 | K14: 6
... B38: ○ | C38: 17301-43770 | D38: SC024-110 | H38: 24Pコントローラ | I38: 1 | J38: 13 | K38: 4
C39: 17301-43730 | D39: IOX012-010 | H39: 12P入出力拡張モジュール | I39: 1 | J39: 3 | K39: 2
B40: E | C40: 17301-43740 | D40: IOX024-020 | H40: 24P入出力拡張モジュール | I40: 1 | J40: 7 | K40: 8
B41: ○ | C41: 17301-43741 | D41: IOX024-120 | H41: 24P入出力拡張モジュール | I41: 1 | J41: 7 | K41: 8
B42: ○ | C42: 17301-43742 | D42: IOX024-120 | H42: 24P入出力拡張モジュール(500kbps) | I42: 1 | J42: 7 | K42: 8
B43: ○ | C43: 17301-43760 | D43: OX024-110 | H43: リレー駆動用モジュール(500kbps) | I43: 1 | J43: 0 | K43: 16
C44: 17301-43510 | D44: GPSキット | H44: WS-403
B45: ○ | C45: 17301-43470 | D45: XL104-0019(Large) | I45: 3 | J45: 31 | K45: 33
B46: ○ | C46: 17301-43480 | D46: XL104-0029(Small) | I46: 3 | J46: 40 | K46: 24
B47: - | C47: 17301-43490 | D47: XL104-0000(Full) | I47: 3 | J47: 48 | K47: 40
B48: ○ | C48: 17301-43580 | D48: SC050-120 | H48: 50PSafty
C49: 赤字：ＥＣＡＤシンボル有
C50: コントローラを組立図の部品表のせるときには、品番：機種品番、品名：コントローラAssyとして登録してください。コントローラAssyの子部品は、コントローラ（プログラムなし）+メインプログラム+パラメータファイルが入ります。
D52: メインプログラム
B53: Active | C53: 機種 | D53: コントローラ品番(ASSY) | E53: Version | F53: 帳票No | G53: Δ | H53: PLUS1(プログラムなし） | I53: プログラム | J53: パラメータファイル | K53: 備考 | L53: SN | M53: SN2 | N53: SN3 | O53: SN4 | P53: 設計変更理由 | Q53: PSW | R53: Application ID
B54: ○ | C54: 共通 | D54: 17301-44340 | H54: 17301-43350(DP250) | I54: - | J54: - | Q54: -
B55: E | C55: 5.7'ディスプレイ | D55: 17301-43650 | E55: 1.7 | H55: - | I55: - | J55: - | K55: カメラなし | Q55: 1.7
B56: E | D56: 17301-43651 | E56: 1.7 | H56: - | I56: - | J56: - | K56: カメラあり | Q56: 1.4
B57: E | D57: 17301-43660 | E57: 1.33 | H57: - | I57: - | J57: - | K57: カメラなし | Q57: 1.33
B58: E | D58: 17301-43661 | E58: 1.33 | H58: - | I58: - | J58: - | K58: カメラあり | Q58: 1.33
B59: ○ | D59: 17301-43664 | E59: 1.65 | H59: - | I59: - | J59: - | K59: Stage5対応カメラなし | Q59: 1.5
B60: ○ | D60: 17301-43665 | E60: 1.65 | H60: - | I60: - | J60: - | K60: Stage5対応カメラあり | Q60: 1.5
B61: ○ | D61: 17301-43666 | E61: 1.65 | H61: - | I61: - | J61: - | K61: L5E専用コストダウン品 | Q61: 1.5
B62: ○ | D62: 07143-00044 | E62: 1 | H62: - | K62: C10-4専用
B63: E | C63: A12A | D63: 05542-00024 | E63: V1.09 | F63: 55511 | G63: 9 | H63: 17301-43360(MC050-055) | I63: 05542-00026_09 | J63: 05542_00027_09 | K63: 新規 | L63: 126000002~126002171 | P63: 新規 | Q63: 1.06
B64: E | D64: 05542-00114 | E64: V2.12 | F64: 55511 | G64: 4 | H64: 17301-43361(MC050-155) | I64: - | J64: 0554200114v212 | K64: コントローラ切替(MC050-155) | L64: 126002172~126002489 | P64: ディスプレイのモデルチェンジ | Q64: 2.01
...
